Workbook

Sheet Mode d'emploi
B2: OP! — Mon budget familial
B3: Un outil simple et bienveillant pour avancer, à votre rythme.
B6: Bienvenue.
B8: Ce fichier a été pensé pour vous aider à garder une vision claire sur les finances de votre famille, sans prise de tête et à votre rythme.
B9: Il n'y a pas de bonne ou de mauvaise façon de l'utiliser — l'important, c'est de commencer.
B11: Comment ça marche
B13: 1. Dans l'onglet Transactions, notez chaque entrée ou sortie d'argent au fil de l'eau (date, libellé, catégorie, montant).
B14: 2. Chaque mois a son propre onglet (Janvier → Décembre) : la colonne « Réel » s'y met à jour automatiquement depuis vos transactions.
B15: 3. Il vous reste juste à renseigner la colonne « Prévu » en début de mois — votre budget cible.
B16: 4. L'onglet Synthèse annuelle regroupe l'ensemble pour une vue d'ensemble.
B17: 5. L'onglet Mes objectifs vous aide à suivre vos projets d'épargne en famille.
B19: Personnalisez les catégories
... B36: L'équipe OP!

Sheet Synthèse annuelle
B2: Synthèse annuelle
B3: Une vue d'ensemble de votre année financière en famille.
B6: Catégorie | C6: Jan | D6: Fév | E6: Mar | F6: Avr | G6: Mai | H6: Jui | I6: Jui | J6: Aoû | K6: Sep | L6: Oct | M6: Nov | N6: Déc | O6: Total
B7: Revenus | C7: =Janvier!D15 -> 0 | D7: =Février!D15 -> 0 | E7: =Mars!D15 -> 0 | F7: =Avril!D15 -> 0 | G7: =Mai!D15 -> 0 | H7: =Juin!D15 -> 0 | I7: =Juillet!D15 -> 0 | J7: =Août!D15 -> 0 | K7: =Septembre!D15 -> 0 | L7: =Octobre!D15 -> 0 | M7: =Novembre!D15 -> 0 | N7: =Décembre!D15 -> 0 | O7: =SUM(C7:N7) -> 0
B8: Dépenses fixes | C8: =Janvier!D36 -> 0 | D8: =Février!D36 -> 0 | E8: =Mars!D36 -> 0 | F8: =Avril!D36 -> 0 | G8: =Mai!D36 -> 0 | H8: =Juin!D36 -> 0 | I8: =Juillet!D36 -> 0 | J8: =Août!D36 -> 0 | K8: =Septembre!D36 -> 0 | L8: =Octobre!D36 -> 0 | M8: =Novembre!D36 -> 0 | N8: =Décembre!D36 -> 0 | O8: =SUM(C8:N8) -> 0
B9: Dépenses courantes | C9: =Janvier!D54 -> 0 | D9: =Février!D54 -> 0 | E9: =Mars!D54 -> 0 | F9: =Avril!D54 -> 0 | G9: =Mai!D54 -> 0 | H9: =Juin!D54 -> 0 | I9: =Juillet!D54 -> 0 | J9: =Août!D54 -> 0 | K9: =Septembre!D54 -> 0 | L9: =Octobre!D54 -> 0 | M9: =Novembre!D54 -> 0 | N9: =Décembre!D54 -> 0 | O9: =SUM(C9:N9) -> 0
B10: Épargne | C10: =Janvier!D64 -> 0 | D10: =Février!D64 -> 0 | E10: =Mars!D64 -> 0 | F10: =Avril!D64 -> 0 | G10: =Mai!D64 -> 0 | H10: =Juin!D64 -> 0 | I10: =Juillet!D64 -> 0 | J10: =Août!D64 -> 0 | K10: =Septembre!D64 -> 0 | L10: =Octobre!D64 -> 0 | M10: =Novembre!D64 -> 0 | N10: =Décembre!D64 -> 0 | O10: =SUM(C10:N10) -> 0
B11: Reste à vivre | C11: =C7-C8-C9-C10 -> 0 | D11: =D7-D8-D9-D10 -> 0 | E11: =E7-E8-E9-E10 -> 0 | F11: =F7-F8-F9-F10 -> 0 | G11: =G7-G8-G9-G10 -> 0 | H11: =H7-H8-H9-H10 -> 0 | I11: =I7-I8-I9-I10 -> 0 | J11: =J7-J8-J9-J10 -> 0 | ... N11: =N7-N8-N9-N10 -> 0 | O11: =SUM(C11:N11) -> 0
B14: Revenus de l'année | E14: Dépenses de l'année | H14: Épargne de l'année | K14: Reste à vivre total
B15: =O7 -> 0 | E15: =O8+O9 -> 0 | H15: =O10 -> 0 | K15: =O11 -> 0

Sheet Transactions
B2: Mes transactions
B3: Notez ici chaque entrée ou sortie d'argent — les onglets mensuels se mettent à jour automatiquement.
B5: Astuce : pour une dépense, utilisez la catégorie exacte de l'onglet mensuel (ex. « Courses alimentaires »). Pour une nouvelle catégorie, ajoutez-la d'abord dans le mois concerné puis saisissez-la ici à l'identique.
B7: Date | C7: Libellé | D7: Catégorie | E7: Type | F7: Montant | G7: Mois
G8: =IF(B8="","",CHOOSE(MONTH(B8),"Janvier","Février","Mars","Avril","Mai","Juin","Juillet","Août","Septembre","Octobre","Novembre","Décembre"))
G9: =IF(B9="","",CHOOSE(MONTH(B9),"Janvier","Février","Mars","Avril","Mai","Juin","Juillet","Août","Septembre","Octobre","Novembre","Décembre"))
G10: =IF(B10="","",CHOOSE(MONTH(B10),"Janvier","Février","Mars","Avril","Mai","Juin","Juillet","Août","Septembre","Octobre","Novembre","Décembre"))
G11: =IF(B11="","",CHOOSE(MONTH(B11),"Janvier","Février","Mars","Avril","Mai","Juin","Juillet","Août","Septembre","Octobre","Novembre","Décembre"))
G12: =IF(B12="","",CHOOSE(MONTH(B12),"Janvier","Février","Mars","Avril","Mai","Juin","Juillet","Août","Septembre","Octobre","Novembre","Décembre"))
G13: =IF(B13="","",CHOOSE(MONTH(B13),"Janvier","Février","Mars","Avril","Mai","Juin","Juillet","Août","Septembre","Octobre","Novembre","Décembre"))
G14: =IF(B14="","",CHOOSE(MONTH(B14),"Janvier","Février","Mars","Avril","Mai","Juin","Juillet","Août","Septembre","Octobre","Novembre","Décembre"))
G15: =IF(B15="","",CHOOSE(MONTH(B15),"Janvier","Février","Mars","Avril","Mai","Juin","Juillet","Août","Septembre","Octobre","Novembre","Décembre"))
G16: =IF(B16="","",CHOOSE(MONTH(B16),"Janvier","Février","Mars","Avril","Mai","Juin","Juillet","Août","Septembre","Octobre","Novembre","Décembre"))
G17: =IF(B17="","",CHOOSE(MONTH(B17),"Janvier","Février","Mars","Avril","Mai","Juin","Juillet","Août","Septembre","Octobre","Novembre","Décembre"))
G18: =IF(B18="","",CHOOSE(MONTH(B18),"Janvier","Février","Mars","Avril","Mai","Juin","Juillet","Août","Septembre","Octobre","Novembre","Décembre"))
G19: =IF(B19="","",CHOOSE(MONTH(B19),"Janvier","Février","Mars","Avril","Mai","Juin","Juillet","Août","Septembre","Octobre","Novembre","Décembre"))
... G307: =IF(B307="","",CHOOSE(MONTH(B307),"Janvier","Février","Mars","Avril","Mai","Juin","Juillet","Août","Septembre","Octobre","Novembre","Décembre"))
B309: OP! · op-parents.fr

Sheet _Listes
A1: Catégorie | B1: Type
A2: Salaire parent 1 | B2: Revenu
A3: Salaire parent 2 | B3: Dépense fixe
A4: Allocations familiales / CAF | B4: Dépense courante
A5: Autres revenus | B5: Épargne
A6: Loyer / Crédit immobilier
A7: Charges / Copropriété
A8: Électricité / Gaz
A9: Eau
A10: Internet / Téléphone
A11: Assurance habitation
A12: Assurance voiture
A13: Mutuelle santé
A14: Impôts (prélèvement)
A15: Crèche / Garde d'enfants
A16: Cantine scolaire
A17: Abonnements (streaming, salle…)
... A30: Livret enfant

Sheet Janvier
B2: Mon budget — Janvier
B3: Le « Réel » se met à jour automatiquement depuis l'onglet Transactions.
B6: Catégorie | C6: Prévu | D6: Réel | E6: Écart
B7: Revenus
B8: Salaire parent 1 | D8: =IFERROR(IF(B8="",0,SUMIFS(Transactions!$F:$F,Transactions!$G:$G,"Janvier",Transactions!$D:$D,B8)),0) -> 0 | E8: =IFERROR(C8-D8,0) -> 0
B9: Salaire parent 2 | D9: =IFERROR(IF(B9="",0,SUMIFS(Transactions!$F:$F,Transactions!$G:$G,"Janvier",Transactions!$D:$D,B9)),0) -> 0 | E9: =IFERROR(C9-D9,0) -> 0
B10: Allocations familiales / CAF | D10: =IFERROR(IF(B10="",0,SUMIFS(Transactions!$F:$F,Transactions!$G:$G,"Janvier",Transactions!$D:$D,B10)),0) -> 0 | E10: =IFERROR(C10-D10,0) -> 0
B11: Autres revenus | D11: =IFERROR(IF(B11="",0,SUMIFS(Transactions!$F:$F,Transactions!$G:$G,"Janvier",Transactions!$D:$D,B11)),0) -> 0 | E11: =IFERROR(C11-D11,0) -> 0
D12: =IFERROR(IF(B12="",0,SUMIFS(Transactions!$F:$F,Transactions!$G:$G,"Janvier",Transactions!$D:$D,B12)),0) -> 0 | E12: =IFERROR(C12-D12,0) -> 0
D13: =IFERROR(IF(B13="",0,SUMIFS(Transactions!$F:$F,Transactions!$G:$G,"Janvier",Transactions!$D:$D,B13)),0) -> 0 | E13: =IFERROR(C13-D13,0) -> 0
D14: =IFERROR(IF(B14="",0,SUMIFS(Transactions!$F:$F,Transactions!$G:$G,"Janvier",Transactions!$D:$D,B14)),0) -> 0 | E14: =IFERROR(C14-D14,0) -> 0
B15: Total revenus | C15: =SUM(C8:C14) -> 0 | D15: =SUM(D8:D14) -> 0 | E15: =SUM(E8:E14) -> 0
B17: Dépenses fixes
B18: Loyer / Crédit immobilier | D18: =IFERROR(IF(B18="",0,SUMIFS(Transactions!$F:$F,Transactions!$G:$G,"Janvier",Transactions!$D:$D,B18)),0) -> 0 | E18: =IFERROR(C18-D18,0) -> 0
B19: Charges / Copropriété | D19: =IFERROR(IF(B19="",0,SUMIFS(Transactions!$F:$F,Transactions!$G:$G,"Janvier",Transactions!$D:$D,B19)),0) -> 0 | E19: =IFERROR(C19-D19,0) -> 0
B20: Électricité / Gaz | D20: =IFERROR(IF(B20="",0,SUMIFS(Transactions!$F:$F,Transactions!$G:$G,"Janvier",Transactions!$D:$D,B20)),0) -> 0 | E20: =IFERROR(C20-D20,0) -> 0
B21: Eau | D21: =IFERROR(IF(B21="",0,SUMIFS(Transactions!$F:$F,Transactions!$G:$G,"Janvier",Transactions!$D:$D,B21)),0) -> 0 | E21: =IFERROR(C21-D21,0) -> 0
B22: Internet / Téléphone | D22: =IFERROR(IF(B22="",0,SUMIFS(Transactions!$F:$F,Transactions!$G:$G,"Janvier",Transactions!$D:$D,B22)),0) -> 0 | E22: =IFERROR(C22-D22,0) -> 0
B23: Assurance habitation | D23: =IFERROR(IF(B23="",0,SUMIFS(Transactions!$F:$F,Transactions!$G:$G,"Janvier",Transactions!$D:$D,B23)),0) -> 0 | E23: =IFERROR(C23-D23,0) -> 0
B24: Assurance voiture | D24: =IFERROR(IF(B24="",0,SUMIFS(Transactions!$F:$F,Transactions!$G:$G,"Janvier",Transactions!$D:$D,B24)),0) -> 0 | E24: =IFERROR(C24-D24,0) -> 0
B25: Mutuelle santé | D25: =IFERROR(IF(B25="",0,SUMIFS(Transactions!$F:$F,Transactions!$G:$G,"Janvier",Transactions!$D:$D,B25)),0) -> 0 | E25: =IFERROR(C25-D25,0) -> 0
B26: Impôts (prélèvement) | D26: =IFERROR(IF(B26="",0,SUMIFS(Transactions!$F:$F,Transactions!$G:$G,"Janvier",Transactions!$D:$D,B26)),0) -> 0 | E26: =IFERROR(C26-D26,0) -> 0
B27: Crèche / Garde d'enfants | D27: =IFERROR(IF(B27="",0,SUMIFS(Transactions!$F:$F,Transactions!$G:$G,"Janvier",Transactions!$D:$D,B27)),0) -> 0 | E27: =IFERROR(C27-D27,0) -> 0
B28: Cantine scolaire | D28: =IFERROR(IF(B28="",0,SUMIFS(Transactions!$F:$F,Transactions!$G:$G,"Janvier",Transactions!$D:$D,B28)),0) -> 0 | E28: =IFERROR(C28-D28,0) -> 0
B29: Abonnements (streaming, salle…) | D29: =IFERROR(IF(B29="",0,SUMIFS(Transactions!$F:$F,Transactions!$G:$G,"Janvier",Transactions!$D:$D,B29)),0) -> 0 | E29: =IFERROR(C29-D29,0) -> 0
D30: =IFERROR(IF(B30="",0,SUMIFS(Transactions!$F:$F,Transactions!$G:$G,"Janvier",Transactions!$D:$D,B30)),0) -> 0 | E30: =IFERROR(C30-D30,0) -> 0
D31: =IFERROR(IF(B31="",0,SUMIFS(Transactions!$F:$F,Transactions!$G:$G,"Janvier",Transactions!$D:$D,B31)),0) -> 0 | E31: =IFERROR(C31-D31,0) -> 0
D32: =IFERROR(IF(B32="",0,SUMIFS(Transactions!$F:$F,Transactions!$G:$G,"Janvier",Transactions!$D:$D,B32)),0) -> 0 | E32: =IFERROR(C32-D32,0) -> 0
D33: =IFERROR(IF(B33="",0,SUMIFS(Transactions!$F:$F,Transactions!$G:$G,"Janvier",Transactions!$D:$D,B33)),0) -> 0 | E33: =IFERROR(C33-D33,0) -> 0
D34: =IFERROR(IF(B34="",0,SUMIFS(Transactions!$F:$F,Transactions!$G:$G,"Janvier",Transactions!$D:$D,B34)),0) -> 0 | E34: =IFERROR(C34-D34,0) -> 0
D35: =IFERROR(IF(B35="",0,SUMIFS(Transactions!$F:$F,Transactions!$G:$G,"Janvier",Transactions!$D:$D,B35)),0) -> 0 | E35: =IFERROR(C35-D35,0) -> 0
B36: Total dépenses fixes | C36: =SUM(C18:C35) -> 0 | D36: =SUM(D18:D35) -> 0 | E36: =SUM(E18:E35) -> 0
B38: Dépenses courantes
B39: Courses alimentaires | D39: =IFERROR(IF(B39="",0,SUMIFS(Transactions!$F:$F,Transactions!$G:$G,"Janvier",Transactions!$D:$D,B39)),0) -> 0 | E39: =IFERROR(C39-D39,0) -> 0
B40: Transport / Carburant | D40: =IFERROR(IF(B40="",0,SUMIFS(Transactions!$F:$F,Transactions!$G:$G,"Janvier",Transactions!$D:$D,B40)),0) -> 0 | E40: =IFERROR(C40-D40,0) -> 0
B41: Vêtements famille | D41: =IFERROR(IF(B41="",0,SUMIFS(Transactions!$F:$F,Transactions!$G:$G,"Janvier",Transactions!$D:$D,B41)),0) -> 0 | E41: =IFERROR(C41-D41,0) -> 0
B42: Enfants (fournitures, activités) | D42: =IFERROR(IF(B42="",0,SUMIFS(Transactions!$F:$F,Transactions!$G:$G,"Janvier",Transactions!$D:$D,B42)),0) -> 0 | E42: =IFERROR(C42-D42,0) -> 0
B43: Santé (pharmacie, médecin) | D43: =IFERROR(IF(B43="",0,SUMIFS(Transactions!$F:$F,Transactions!$G:$G,"Janvier",Transactions!$D:$D,B43)),0) -> 0 | E43: =IFERROR(C43-D43,0) -> 0
B44: Loisirs / Sorties | D44: =IFERROR(IF(B44="",0,SUMIFS(Transactions!$F:$F,Transactions!$G:$G,"Janvier",Transactions!$D:$D,B44)),0) -> 0 | E44: =IFERROR(C44-D44,0) -> 0
B45: Restaurants / À emporter | D45: =IFERROR(IF(B45="",0,SUMIFS(Transactions!$F:$F,Transactions!$G:$G,"Janvier",Transactions!$D:$D,B45)),0) -> 0 | E45: =IFERROR(C45-D45,0) -> 0
...

Sheet Février
B2: Mon budget — Février
B3: Le « Réel » se met à jour automatiquement depuis l'onglet Transactions.
B6: Catégorie | C6: Prévu | D6: Réel | E6: Écart
B7: Revenus
B8: Salaire parent 1 | D8: =IFERROR(IF(B8="",0,SUMIFS(Transactions!$F:$F,Transactions!$G:$G,"Février",Transactions!$D:$D,B8)),0) -> 0 | E8: =IFERROR(C8-D8,0) -> 0
B9: Salaire parent 2 | D9: =IFERROR(IF(B9="",0,SUMIFS(Transactions!$F:$F,Transactions!$G:$G,"Février",Transactions!$D:$D,B9)),0) -> 0 | E9: =IFERROR(C9-D9,0) -> 0
B10: Allocations familiales / CAF | D10: =IFERROR(IF(B10="",0,SUMIFS(Transactions!$F:$F,Transactions!$G:$G,"Février",Transactions!$D:$D,B10)),0) -> 0 | E10: =IFERROR(C10-D10,0) -> 0
B11: Autres revenus | D11: =IFERROR(IF(B11="",0,SUMIFS(Transactions!$F:$F,Transactions!$G:$G,"Février",Transactions!$D:$D,B11)),0) -> 0 | E11: =IFERROR(C11-D11,0) -> 0
D12: =IFERROR(IF(B12="",0,SUMIFS(Transactions!$F:$F,Transactions!$G:$G,"Février",Transactions!$D:$D,B12)),0) -> 0 | E12: =IFERROR(C12-D12,0) -> 0
D13: =IFERROR(IF(B13="",0,SUMIFS(Transactions!$F:$F,Transactions!$G:$G,"Février",Transactions!$D:$D,B13)),0) -> 0 | E13: =IFERROR(C13-D13,0) -> 0
D14: =IFERROR(IF(B14="",0,SUMIFS(Transactions!$F:$F,Transactions!$G:$G,"Février",Transactions!$D:$D,B14)),0) -> 0 | E14: =IFERROR(C14-D14,0) -> 0
B15: Total revenus | C15: =SUM(C8:C14) -> 0 | D15: =SUM(D8:D14) -> 0 | E15: =SUM(E8:E14) -> 0
B17: Dépenses fixes
B18: Loyer / Crédit immobilier | D18: =IFERROR(IF(B18="",0,SUMIFS(Transactions!$F:$F,Transactions!$G:$G,"Février",Transactions!$D:$D,B18)),0) -> 0 | E18: =IFERROR(C18-D18,0) -> 0
B19: Charges / Copropriété | D19: =IFERROR(IF(B19="",0,SUMIFS(Transactions!$F:$F,Transactions!$G:$G,"Février",Transactions!$D:$D,B19)),0) -> 0 | E19: =IFERROR(C19-D19,0) -> 0
B20: Électricité / Gaz | D20: =IFERROR(IF(B20="",0,SUMIFS(Transactions!$F:$F,Transactions!$G:$G,"Février",Transactions!$D:$D,B20)),0) -> 0 | E20: =IFERROR(C20-D20,0) -> 0
B21: Eau | D21: =IFERROR(IF(B21="",0,SUMIFS(Transactions!$F:$F,Transactions!$G:$G,"Février",Transactions!$D:$D,B21)),0) -> 0 | E21: =IFERROR(C21-D21,0) -> 0
B22: Internet / Téléphone | D22: =IFERROR(IF(B22="",0,SUMIFS(Transactions!$F:$F,Transactions!$G:$G,"Février",Transactions!$D:$D,B22)),0) -> 0 | E22: =IFERROR(C22-D22,0) -> 0
B23: Assurance habitation | D23: =IFERROR(IF(B23="",0,SUMIFS(Transactions!$F:$F,Transactions!$G:$G,"Février",Transactions!$D:$D,B23)),0) -> 0 | E23: =IFERROR(C23-D23,0) -> 0
B24: Assurance voiture | D24: =IFERROR(IF(B24="",0,SUMIFS(Transactions!$F:$F,Transactions!$G:$G,"Février",Transactions!$D:$D,B24)),0) -> 0 | E24: =IFERROR(C24-D24,0) -> 0
B25: Mutuelle santé | D25: =IFERROR(IF(B25="",0,SUMIFS(Transactions!$F:$F,Transactions!$G:$G,"Février",Transactions!$D:$D,B25)),0) -> 0 | E25: =IFERROR(C25-D25,0) -> 0
B26: Impôts (prélèvement) | D26: =IFERROR(IF(B26="",0,SUMIFS(Transactions!$F:$F,Transactions!$G:$G,"Février",Transactions!$D:$D,B26)),0) -> 0 | E26: =IFERROR(C26-D26,0) -> 0
B27: Crèche / Garde d'enfants | D27: =IFERROR(IF(B27="",0,SUMIFS(Transactions!$F:$F,Transactions!$G:$G,"Février",Transactions!$D:$D,B27)),0) -> 0 | E27: =IFERROR(C27-D27,0) -> 0
B28: Cantine scolaire | D28: =IFERROR(IF(B28="",0,SUMIFS(Transactions!$F:$F,Transactions!$G:$G,"Février",Transactions!$D:$D,B28)),0) -> 0 | E28: =IFERROR(C28-D28,0) -> 0
B29: Abonnements (streaming, salle…) | D29: =IFERROR(IF(B29="",0,SUMIFS(Transactions!$F:$F,Transactions!$G:$G,"Février",Transactions!$D:$D,B29)),0) -> 0 | E29: =IFERROR(C29-D29,0) -> 0
D30: =IFERROR(IF(B30="",0,SUMIFS(Transactions!$F:$F,Transactions!$G:$G,"Février",Transactions!$D:$D,B30)),0) -> 0 | E30: =IFERROR(C30-D30,0) -> 0
D31: =IFERROR(IF(B31="",0,SUMIFS(Transactions!$F:$F,Transactions!$G:$G,"Février",Transactions!$D:$D,B31)),0) -> 0 | E31: =IFERROR(C31-D31,0) -> 0
D32: =IFERROR(IF(B32="",0,SUMIFS(Transactions!$F:$F,Transactions!$G:$G,"Février",Transactions!$D:$D,B32)),0) -> 0 | E32: =IFERROR(C32-D32,0) -> 0
D33: =IFERROR(IF(B33="",0,SUMIFS(Transactions!$F:$F,Transactions!$G:$G,"Février",Transactions!$D:$D,B33)),0) -> 0 | E33: =IFERROR(C33-D33,0) -> 0
D34: =IFERROR(IF(B34="",0,SUMIFS(Transactions!$F:$F,Transactions!$G:$G,"Février",Transactions!$D:$D,B34)),0) -> 0 | E34: =IFERROR(C34-D34,0) -> 0
D35: =IFERROR(IF(B35="",0,SUMIFS(Transactions!$F:$F,Transactions!$G:$G,"Février",Transactions!$D:$D,B35)),0) -> 0 | E35: =IFERROR(C35-D35,0) -> 0
B36: Total dépenses fixes | C36: =SUM(C18:C35) -> 0 | D36: =SUM(D18:D35) -> 0 | E36: =SUM(E18:E35) -> 0
B38: Dépenses courantes
B39: Courses alimentaires | D39: =IFERROR(IF(B39="",0,SUMIFS(Transactions!$F:$F,Transactions!$G:$G,"Février",Transactions!$D:$D,B39)),0) -> 0 | E39: =IFERROR(C39-D39,0) -> 0
B40: Transport / Carburant | D40: =IFERROR(IF(B40="",0,SUMIFS(Transactions!$F:$F,Transactions!$G:$G,"Février",Transactions!$D:$D,B40)),0) -> 0 | E40: =IFERROR(C40-D40,0) -> 0
B41: Vêtements famille | D41: =IFERROR(IF(B41="",0,SUMIFS(Transactions!$F:$F,Transactions!$G:$G,"Février",Transactions!$D:$D,B41)),0) -> 0 | E41: =IFERROR(C41-D41,0) -> 0
B42: Enfants (fournitures, activités) | D42: =IFERROR(IF(B42="",0,SUMIFS(Transactions!$F:$F,Transactions!$G:$G,"Février",Transactions!$D:$D,B42)),0) -> 0 | E42: =IFERROR(C42-D42,0) -> 0
B43: Santé (pharmacie, médecin) | D43: =IFERROR(IF(B43="",0,SUMIFS(Transactions!$F:$F,Transactions!$G:$G,"Février",Transactions!$D:$D,B43)),0) -> 0 | E43: =IFERROR(C43-D43,0) -> 0
B44: Loisirs / Sorties | D44: =IFERROR(IF(B44="",0,SUMIFS(Transactions!$F:$F,Transactions!$G:$G,"Février",Transactions!$D:$D,B44)),0) -> 0 | E44: =IFERROR(C44-D44,0) -> 0
B45: Restaurants / À emporter | D45: =IFERROR(IF(B45="",0,SUMIFS(Transactions!$F:$F,Transactions!$G:$G,"Février",Transactions!$D:$D,B45)),0) -> 0 | E45: =IFERROR(C45-D45,0) -> 0
...

Sheet Mars
B2: Mon budget — Mars
B3: Le « Réel » se met à jour automatiquement depuis l'onglet Transactions.
B6: Catégorie | C6: Prévu | D6: Réel | E6: Écart
B7: Revenus
B8: Salaire parent 1 | D8: =IFERROR(IF(B8="",0,SUMIFS(Transactions!$F:$F,Transactions!$G:$G,"Mars",Transactions!$D:$D,B8)),0) -> 0 | E8: =IFERROR(C8-D8,0) -> 0
B9: Salaire parent 2 | D9: =IFERROR(IF(B9="",0,SUMIFS(Transactions!$F:$F,Transactions!$G:$G,"Mars",Transactions!$D:$D,B9)),0) -> 0 | E9: =IFERROR(C9-D9,0) -> 0
B10: Allocations familiales / CAF | D10: =IFERROR(IF(B10="",0,SUMIFS(Transactions!$F:$F,Transactions!$G:$G,"Mars",Transactions!$D:$D,B10)),0) -> 0 | E10: =IFERROR(C10-D10,0) -> 0
B11: Autres revenus | D11: =IFERROR(IF(B11="",0,SUMIFS(Transactions!$F:$F,Transactions!$G:$G,"Mars",Transactions!$D:$D,B11)),0) -> 0 | E11: =IFERROR(C11-D11,0) -> 0
D12: =IFERROR(IF(B12="",0,SUMIFS(Transactions!$F:$F,Transactions!$G:$G,"Mars",Transactions!$D:$D,B12)),0) -> 0 | E12: =IFERROR(C12-D12,0) -> 0
D13: =IFERROR(IF(B13="",0,SUMIFS(Transactions!$F:$F,Transactions!$G:$G,"Mars",Transactions!$D:$D,B13)),0) -> 0 | E13: =IFERROR(C13-D13,0) -> 0
D14: =IFERROR(IF(B14="",0,SUMIFS(Transactions!$F:$F,Transactions!$G:$G,"Mars",Transactions!$D:$D,B14)),0) -> 0 | E14: =IFERROR(C14-D14,0) -> 0
B15: Total revenus | C15: =SUM(C8:C14) -> 0 | D15: =SUM(D8:D14) -> 0 | E15: =SUM(E8:E14) -> 0
B17: Dépenses fixes
B18: Loyer / Crédit immobilier | D18: =IFERROR(IF(B18="",0,SUMIFS(Transactions!$F:$F,Transactions!$G:$G,"Mars",Transactions!$D:$D,B18)),0) -> 0 | E18: =IFERROR(C18-D18,0) -> 0
B19: Charges / Copropriété | D19: =IFERROR(IF(B19="",0,SUMIFS(Transactions!$F:$F,Transactions!$G:$G,"Mars",Transactions!$D:$D,B19)),0) -> 0 | E19: =IFERROR(C19-D19,0) -> 0
B20: Électricité / Gaz | D20: =IFERROR(IF(B20="",0,SUMIFS(Transactions!$F:$F,Transactions!$G:$G,"Mars",Transactions!$D:$D,B20)),0) -> 0 | E20: =IFERROR(C20-D20,0) -> 0
B21: Eau | D21: =IFERROR(IF(B21="",0,SUMIFS(Transactions!$F:$F,Transactions!$G:$G,"Mars",Transactions!$D:$D,B21)),0) -> 0 | E21: =IFERROR(C21-D21,0) -> 0
B22: Internet / Téléphone | D22: =IFERROR(IF(B22="",0,SUMIFS(Transactions!$F:$F,Transactions!$G:$G,"Mars",Transactions!$D:$D,B22)),0) -> 0 | E22: =IFERROR(C22-D22,0) -> 0
B23: Assurance habitation | D23: =IFERROR(IF(B23="",0,SUMIFS(Transactions!$F:$F,Transactions!$G:$G,"Mars",Transactions!$D:$D,B23)),0) -> 0 | E23: =IFERROR(C23-D23,0) -> 0
B24: Assurance voiture | D24: =IFERROR(IF(B24="",0,SUMIFS(Transactions!$F:$F,Transactions!$G:$G,"Mars",Transactions!$D:$D,B24)),0) -> 0 | E24: =IFERROR(C24-D24,0) -> 0
B25: Mutuelle santé | D25: =IFERROR(IF(B25="",0,SUMIFS(Transactions!$F:$F,Transactions!$G:$G,"Mars",Transactions!$D:$D,B25)),0) -> 0 | E25: =IFERROR(C25-D25,0) -> 0
B26: Impôts (prélèvement) | D26: =IFERROR(IF(B26="",0,SUMIFS(Transactions!$F:$F,Transactions!$G:$G,"Mars",Transactions!$D:$D,B26)),0) -> 0 | E26: =IFERROR(C26-D26,0) -> 0
B27: Crèche / Garde d'enfants | D27: =IFERROR(IF(B27="",0,SUMIFS(Transactions!$F:$F,Transactions!$G:$G,"Mars",Transactions!$D:$D,B27)),0) -> 0 | E27: =IFERROR(C27-D27,0) -> 0
B28: Cantine scolaire | D28: =IFERROR(IF(B28="",0,SUMIFS(Transactions!$F:$F,Transactions!$G:$G,"Mars",Transactions!$D:$D,B28)),0) -> 0 | E28: =IFERROR(C28-D28,0) -> 0
B29: Abonnements (streaming, salle…) | D29: =IFERROR(IF(B29="",0,SUMIFS(Transactions!$F:$F,Transactions!$G:$G,"Mars",Transactions!$D:$D,B29)),0) -> 0 | E29: =IFERROR(C29-D29,0) -> 0
D30: =IFERROR(IF(B30="",0,SUMIFS(Transactions!$F:$F,Transactions!$G:$G,"Mars",Transactions!$D:$D,B30)),0) -> 0 | E30: =IFERROR(C30-D30,0) -> 0
D31: =IFERROR(IF(B31="",0,SUMIFS(Transactions!$F:$F,Transactions!$G:$G,"Mars",Transactions!$D:$D,B31)),0) -> 0 | E31: =IFERROR(C31-D31,0) -> 0
D32: =IFERROR(IF(B32="",0,SUMIFS(Transactions!$F:$F,Transactions!$G:$G,"Mars",Transactions!$D:$D,B32)),0) -> 0 | E32: =IFERROR(C32-D32,0) -> 0
D33: =IFERROR(IF(B33="",0,SUMIFS(Transactions!$F:$F,Transactions!$G:$G,"Mars",Transactions!$D:$D,B33)),0) -> 0 | E33: =IFERROR(C33-D33,0) -> 0
D34: =IFERROR(IF(B34="",0,SUMIFS(Transactions!$F:$F,Transactions!$G:$G,"Mars",Transactions!$D:$D,B34)),0) -> 0 | E34: =IFERROR(C34-D34,0) -> 0
D35: =IFERROR(IF(B35="",0,SUMIFS(Transactions!$F:$F,Transactions!$G:$G,"Mars",Transactions!$D:$D,B35)),0) -> 0 | E35: =IFERROR(C35-D35,0) -> 0
B36: Total dépenses fixes | C36: =SUM(C18:C35) -> 0 | D36: =SUM(D18:D35) -> 0 | E36: =SUM(E18:E35) -> 0
B38: Dépenses courantes
B39: Courses alimentaires | D39: =IFERROR(IF(B39="",0,SUMIFS(Transactions!$F:$F,Transactions!$G:$G,"Mars",Transactions!$D:$D,B39)),0) -> 0 | E39: =IFERROR(C39-D39,0) -> 0
B40: Transport / Carburant | D40: =IFERROR(IF(B40="",0,SUMIFS(Transactions!$F:$F,Transactions!$G:$G,"Mars",Transactions!$D:$D,B40)),0) -> 0 | E40: =IFERROR(C40-D40,0) -> 0
B41: Vêtements famille | D41: =IFERROR(IF(B41="",0,SUMIFS(Transactions!$F:$F,Transactions!$G:$G,"Mars",Transactions!$D:$D,B41)),0) -> 0 | E41: =IFERROR(C41-D41,0) -> 0
B42: Enfants (fournitures, activités) | D42: =IFERROR(IF(B42="",0,SUMIFS(Transactions!$F:$F,Transactions!$G:$G,"Mars",Transactions!$D:$D,B42)),0) -> 0 | E42: =IFERROR(C42-D42,0) -> 0
B43: Santé (pharmacie, médecin) | D43: =IFERROR(IF(B43="",0,SUMIFS(Transactions!$F:$F,Transactions!$G:$G,"Mars",Transactions!$D:$D,B43)),0) -> 0 | E43: =IFERROR(C43-D43,0) -> 0
B44: Loisirs / Sorties | D44: =IFERROR(IF(B44="",0,SUMIFS(Transactions!$F:$F,Transactions!$G:$G,"Mars",Transactions!$D:$D,B44)),0) -> 0 | E44: =IFERROR(C44-D44,0) -> 0
B45: Restaurants / À emporter | D45: =IFERROR(IF(B45="",0,SUMIFS(Transactions!$F:$F,Transactions!$G:$G,"Mars",Transactions!$D:$D,B45)),0) -> 0 | E45: =IFERROR(C45-D45,0) -> 0
...

Sheet Avril
B2: Mon budget — Avril
B3: Le « Réel » se met à jour automatiquement depuis l'onglet Transactions.
B6: Catégorie | C6: Prévu | D6: Réel | E6: Écart
B7: Revenus
B8: Salaire parent 1 | D8: =IFERROR(IF(B8="",0,SUMIFS(Transactions!$F:$F,Transactions!$G:$G,"Avril",Transactions!$D:$D,B8)),0) -> 0 | E8: =IFERROR(C8-D8,0) -> 0
B9: Salaire parent 2 | D9: =IFERROR(IF(B9="",0,SUMIFS(Transactions!$F:$F,Transactions!$G:$G,"Avril",Transactions!$D:$D,B9)),0) -> 0 | E9: =IFERROR(C9-D9,0) -> 0
B10: Allocations familiales / CAF | D10: =IFERROR(IF(B10="",0,SUMIFS(Transactions!$F:$F,Transactions!$G:$G,"Avril",Transactions!$D:$D,B10)),0) -> 0 | E10: =IFERROR(C10-D10,0) -> 0
B11: Autres revenus | D11: =IFERROR(IF(B11="",0,SUMIFS(Transactions!$F:$F,Transactions!$G:$G,"Avril",Transactions!$D:$D,B11)),0) -> 0 | E11: =IFERROR(C11-D11,0) -> 0
D12: =IFERROR(IF(B12="",0,SUMIFS(Transactions!$F:$F,Transactions!$G:$G,"Avril",Transactions!$D:$D,B12)),0) -> 0 | E12: =IFERROR(C12-D12,0) -> 0
D13: =IFERROR(IF(B13="",0,SUMIFS(Transactions!$F:$F,Transactions!$G:$G,"Avril",Transactions!$D:$D,B13)),0) -> 0 | E13: =IFERROR(C13-D13,0) -> 0
D14: =IFERROR(IF(B14="",0,SUMIFS(Transactions!$F:$F,Transactions!$G:$G,"Avril",Transactions!$D:$D,B14)),0) -> 0 | E14: =IFERROR(C14-D14,0) -> 0
B15: Total revenus | C15: =SUM(C8:C14) -> 0 | D15: =SUM(D8:D14) -> 0 | E15: =SUM(E8:E14) -> 0
B17: Dépenses fixes
B18: Loyer / Crédit immobilier | D18: =IFERROR(IF(B18="",0,SUMIFS(Transactions!$F:$F,Transactions!$G:$G,"Avril",Transactions!$D:$D,B18)),0) -> 0 | E18: =IFERROR(C18-D18,0) -> 0
B19: Charges / Copropriété | D19: =IFERROR(IF(B19="",0,SUMIFS(Transactions!$F:$F,Transactions!$G:$G,"Avril",Transactions!$D:$D,B19)),0) -> 0 | E19: =IFERROR(C19-D19,0) -> 0
B20: Électricité / Gaz | D20: =IFERROR(IF(B20="",0,SUMIFS(Transactions!$F:$F,Transactions!$G:$G,"Avril",Transactions!$D:$D,B20)),0) -> 0 | E20: =IFERROR(C20-D20,0) -> 0
B21: Eau | D21: =IFERROR(IF(B21="",0,SUMIFS(Transactions!$F:$F,Transactions!$G:$G,"Avril",Transactions!$D:$D,B21)),0) -> 0 | E21: =IFERROR(C21-D21,0) -> 0
B22: Internet / Téléphone | D22: =IFERROR(IF(B22="",0,SUMIFS(Transactions!$F:$F,Transactions!$G:$G,"Avril",Transactions!$D:$D,B22)),0) -> 0 | E22: =IFERROR(C22-D22,0) -> 0
B23: Assurance habitation | D23: =IFERROR(IF(B23="",0,SUMIFS(Transactions!$F:$F,Transactions!$G:$G,"Avril",Transactions!$D:$D,B23)),0) -> 0 | E23: =IFERROR(C23-D23,0) -> 0
B24: Assurance voiture | D24: =IFERROR(IF(B24="",0,SUMIFS(Transactions!$F:$F,Transactions!$G:$G,"Avril",Transactions!$D:$D,B24)),0) -> 0 | E24: =IFERROR(C24-D24,0) -> 0
B25: Mutuelle santé | D25: =IFERROR(IF(B25="",0,SUMIFS(Transactions!$F:$F,Transactions!$G:$G,"Avril",Transactions!$D:$D,B25)),0) -> 0 | E25: =IFERROR(C25-D25,0) -> 0
B26: Impôts (prélèvement) | D26: =IFERROR(IF(B26="",0,SUMIFS(Transactions!$F:$F,Transactions!$G:$G,"Avril",Transactions!$D:$D,B26)),0) -> 0 | E26: =IFERROR(C26-D26,0) -> 0
B27: Crèche / Garde d'enfants | D27: =IFERROR(IF(B27="",0,SUMIFS(Transactions!$F:$F,Transactions!$G:$G,"Avril",Transactions!$D:$D,B27)),0) -> 0 | E27: =IFERROR(C27-D27,0) -> 0
B28: Cantine scolaire | D28: =IFERROR(IF(B28="",0,SUMIFS(Transactions!$F:$F,Transactions!$G:$G,"Avril",Transactions!$D:$D,B28)),0) -> 0 | E28: =IFERROR(C28-D28,0) -> 0
B29: Abonnements (streaming, salle…) | D29: =IFERROR(IF(B29="",0,SUMIFS(Transactions!$F:$F,Transactions!$G:$G,"Avril",Transactions!$D:$D,B29)),0) -> 0 | E29: =IFERROR(C29-D29,0) -> 0
D30: =IFERROR(IF(B30="",0,SUMIFS(Transactions!$F:$F,Transactions!$G:$G,"Avril",Transactions!$D:$D,B30)),0) -> 0 | E30: =IFERROR(C30-D30,0) -> 0
D31: =IFERROR(IF(B31="",0,SUMIFS(Transactions!$F:$F,Transactions!$G:$G,"Avril",Transactions!$D:$D,B31)),0) -> 0 | E31: =IFERROR(C31-D31,0) -> 0
D32: =IFERROR(IF(B32="",0,SUMIFS(Transactions!$F:$F,Transactions!$G:$G,"Avril",Transactions!$D:$D,B32)),0) -> 0 | E32: =IFERROR(C32-D32,0) -> 0
D33: =IFERROR(IF(B33="",0,SUMIFS(Transactions!$F:$F,Transactions!$G:$G,"Avril",Transactions!$D:$D,B33)),0) -> 0 | E33: =IFERROR(C33-D33,0) -> 0
D34: =IFERROR(IF(B34="",0,SUMIFS(Transactions!$F:$F,Transactions!$G:$G,"Avril",Transactions!$D:$D,B34)),0) -> 0 | E34: =IFERROR(C34-D34,0) -> 0
D35: =IFERROR(IF(B35="",0,SUMIFS(Transactions!$F:$F,Transactions!$G:$G,"Avril",Transactions!$D:$D,B35)),0) -> 0 | E35: =IFERROR(C35-D35,0) -> 0
B36: Total dépenses fixes | C36: =SUM(C18:C35) -> 0 | D36: =SUM(D18:D35) -> 0 | E36: =SUM(E18:E35) -> 0
B38: Dépenses courantes
B39: Courses alimentaires | D39: =IFERROR(IF(B39="",0,SUMIFS(Transactions!$F:$F,Transactions!$G:$G,"Avril",Transactions!$D:$D,B39)),0) -> 0 | E39: =IFERROR(C39-D39,0) -> 0
B40: Transport / Carburant | D40: =IFERROR(IF(B40="",0,SUMIFS(Transactions!$F:$F,Transactions!$G:$G,"Avril",Transactions!$D:$D,B40)),0) -> 0 | E40: =IFERROR(C40-D40,0) -> 0
B41: Vêtements famille | D41: =IFERROR(IF(B41="",0,SUMIFS(Transactions!$F:$F,Transactions!$G:$G,"Avril",Transactions!$D:$D,B41)),0) -> 0 | E41: =IFERROR(C41-D41,0) -> 0
B42: Enfants (fournitures, activités) | D42: =IFERROR(IF(B42="",0,SUMIFS(Transactions!$F:$F,Transactions!$G:$G,"Avril",Transactions!$D:$D,B42)),0) -> 0 | E42: =IFERROR(C42-D42,0) -> 0
B43: Santé (pharmacie, médecin) | D43: =IFERROR(IF(B43="",0,SUMIFS(Transactions!$F:$F,Transactions!$G:$G,"Avril",Transactions!$D:$D,B43)),0) -> 0 | E43: =IFERROR(C43-D43,0) -> 0
B44: Loisirs / Sorties | D44: =IFERROR(IF(B44="",0,SUMIFS(Transactions!$F:$F,Transactions!$G:$G,"Avril",Transactions!$D:$D,B44)),0) -> 0 | E44: =IFERROR(C44-D44,0) -> 0
B45: Restaurants / À emporter | D45: =IFERROR(IF(B45="",0,SUMIFS(Transactions!$F:$F,Transactions!$G:$G,"Avril",Transactions!$D:$D,B45)),0) -> 0 | E45: =IFERROR(C45-D45,0) -> 0
...

Sheet Mai
B2: Mon budget — Mai
B3: Le « Réel » se met à jour automatiquement depuis l'onglet Transactions.
B6: Catégorie | C6: Prévu | D6: Réel | E6: Écart
B7: Revenus
B8: Salaire parent 1 | D8: =IFERROR(IF(B8="",0,SUMIFS(Transactions!$F:$F,Transactions!$G:$G,"Mai",Transactions!$D:$D,B8)),0) -> 0 | E8: =IFERROR(C8-D8,0) -> 0
B9: Salaire parent 2 | D9: =IFERROR(IF(B9="",0,SUMIFS(Transactions!$F:$F,Transactions!$G:$G,"Mai",Transactions!$D:$D,B9)),0) -> 0 | E9: =IFERROR(C9-D9,0) -> 0
B10: Allocations familiales / CAF | D10: =IFERROR(IF(B10="",0,SUMIFS(Transactions!$F:$F,Transactions!$G:$G,"Mai",Transactions!$D:$D,B10)),0) -> 0 | E10: =IFERROR(C10-D10,0) -> 0
B11: Autres revenus | D11: =IFERROR(IF(B11="",0,SUMIFS(Transactions!$F:$F,Transactions!$G:$G,"Mai",Transactions!$D:$D,B11)),0) -> 0 | E11: =IFERROR(C11-D11,0) -> 0
D12: =IFERROR(IF(B12="",0,SUMIFS(Transactions!$F:$F,Transactions!$G:$G,"Mai",Transactions!$D:$D,B12)),0) -> 0 | E12: =IFERROR(C12-D12,0) -> 0
D13: =IFERROR(IF(B13="",0,SUMIFS(Transactions!$F:$F,Transactions!$G:$G,"Mai",Transactions!$D:$D,B13)),0) -> 0 | E13: =IFERROR(C13-D13,0) -> 0
D14: =IFERROR(IF(B14="",0,SUMIFS(Transactions!$F:$F,Transactions!$G:$G,"Mai",Transactions!$D:$D,B14)),0) -> 0 | E14: =IFERROR(C14-D14,0) -> 0
B15: Total revenus | C15: =SUM(C8:C14) -> 0 | D15: =SUM(D8:D14) -> 0 | E15: =SUM(E8:E14) -> 0
B17: Dépenses fixes
B18: Loyer / Crédit immobilier | D18: =IFERROR(IF(B18="",0,SUMIFS(Transactions!$F:$F,Transactions!$G:$G,"Mai",Transactions!$D:$D,B18)),0) -> 0 | E18: =IFERROR(C18-D18,0) -> 0
B19: Charges / Copropriété | D19: =IFERROR(IF(B19="",0,SUMIFS(Transactions!$F:$F,Transactions!$G:$G,"Mai",Transactions!$D:$D,B19)),0) -> 0 | E19: =IFERROR(C19-D19,0) -> 0
B20: Électricité / Gaz | D20: =IFERROR(IF(B20="",0,SUMIFS(Transactions!$F:$F,Transactions!$G:$G,"Mai",Transactions!$D:$D,B20)),0) -> 0 | E20: =IFERROR(C20-D20,0) -> 0
B21: Eau | D21: =IFERROR(IF(B21="",0,SUMIFS(Transactions!$F:$F,Transactions!$G:$G,"Mai",Transactions!$D:$D,B21)),0) -> 0 | E21: =IFERROR(C21-D21,0) -> 0
B22: Internet / Téléphone | D22: =IFERROR(IF(B22="",0,SUMIFS(Transactions!$F:$F,Transactions!$G:$G,"Mai",Transactions!$D:$D,B22)),0) -> 0 | E22: =IFERROR(C22-D22,0) -> 0
B23: Assurance habitation | D23: =IFERROR(IF(B23="",0,SUMIFS(Transactions!$F:$F,Transactions!$G:$G,"Mai",Transactions!$D:$D,B23)),0) -> 0 | E23: =IFERROR(C23-D23,0) -> 0
B24: Assurance voiture | D24: =IFERROR(IF(B24="",0,SUMIFS(Transactions!$F:$F,Transactions!$G:$G,"Mai",Transactions!$D:$D,B24)),0) -> 0 | E24: =IFERROR(C24-D24,0) -> 0
B25: Mutuelle santé | D25: =IFERROR(IF(B25="",0,SUMIFS(Transactions!$F:$F,Transactions!$G:$G,"Mai",Transactions!$D:$D,B25)),0) -> 0 | E25: =IFERROR(C25-D25,0) -> 0
B26: Impôts (prélèvement) | D26: =IFERROR(IF(B26="",0,SUMIFS(Transactions!$F:$F,Transactions!$G:$G,"Mai",Transactions!$D:$D,B26)),0) -> 0 | E26: =IFERROR(C26-D26,0) -> 0
B27: Crèche / Garde d'enfants | D27: =IFERROR(IF(B27="",0,SUMIFS(Transactions!$F:$F,Transactions!$G:$G,"Mai",Transactions!$D:$D,B27)),0) -> 0 | E27: =IFERROR(C27-D27,0) -> 0
B28: Cantine scolaire | D28: =IFERROR(IF(B28="",0,SUMIFS(Transactions!$F:$F,Transactions!$G:$G,"Mai",Transactions!$D:$D,B28)),0) -> 0 | E28: =IFERROR(C28-D28,0) -> 0
B29: Abonnements (streaming, salle…) | D29: =IFERROR(IF(B29="",0,SUMIFS(Transactions!$F:$F,Transactions!$G:$G,"Mai",Transactions!$D:$D,B29)),0) -> 0 | E29: =IFERROR(C29-D29,0) -> 0
D30: =IFERROR(IF(B30="",0,SUMIFS(Transactions!$F:$F,Transactions!$G:$G,"Mai",Transactions!$D:$D,B30)),0) -> 0 | E30: =IFERROR(C30-D30,0) -> 0
D31: =IFERROR(IF(B31="",0,SUMIFS(Transactions!$F:$F,Transactions!$G:$G,"Mai",Transactions!$D:$D,B31)),0) -> 0 | E31: =IFERROR(C31-D31,0) -> 0
D32: =IFERROR(IF(B32="",0,SUMIFS(Transactions!$F:$F,Transactions!$G:$G,"Mai",Transactions!$D:$D,B32)),0) -> 0 | E32: =IFERROR(C32-D32,0) -> 0
D33: =IFERROR(IF(B33="",0,SUMIFS(Transactions!$F:$F,Transactions!$G:$G,"Mai",Transactions!$D:$D,B33)),0) -> 0 | E33: =IFERROR(C33-D33,0) -> 0
D34: =IFERROR(IF(B34="",0,SUMIFS(Transactions!$F:$F,Transactions!$G:$G,"Mai",Transactions!$D:$D,B34)),0) -> 0 | E34: =IFERROR(C34-D34,0) -> 0
D35: =IFERROR(IF(B35="",0,SUMIFS(Transactions!$F:$F,Transactions!$G:$G,"Mai",Transactions!$D:$D,B35)),0) -> 0 | E35: =IFERROR(C35-D35,0) -> 0
B36: Total dépenses fixes | C36: =SUM(C18:C35) -> 0 | D36: =SUM(D18:D35) -> 0 | E36: =SUM(E18:E35) -> 0
B38: Dépenses courantes
B39: Courses alimentaires | D39: =IFERROR(IF(B39="",0,SUMIFS(Transactions!$F:$F,Transactions!$G:$G,"Mai",Transactions!$D:$D,B39)),0) -> 0 | E39: =IFERROR(C39-D39,0) -> 0
B40: Transport / Carburant | D40: =IFERROR(IF(B40="",0,SUMIFS(Transactions!$F:$F,Transactions!$G:$G,"Mai",Transactions!$D:$D,B40)),0) -> 0 | E40: =IFERROR(C40-D40,0) -> 0
B41: Vêtements famille | D41: =IFERROR(IF(B41="",0,SUMIFS(Transactions!$F:$F,Transactions!$G:$G,"Mai",Transactions!$D:$D,B41)),0) -> 0 | E41: =IFERROR(C41-D41,0) -> 0
B42: Enfants (fournitures, activités) | D42: =IFERROR(IF(B42="",0,SUMIFS(Transactions!$F:$F,Transactions!$G:$G,"Mai",Transactions!$D:$D,B42)),0) -> 0 | E42: =IFERROR(C42-D42,0) -> 0
B43: Santé (pharmacie, médecin) | D43: =IFERROR(IF(B43="",0,SUMIFS(Transactions!$F:$F,Transactions!$G:$G,"Mai",Transactions!$D:$D,B43)),0) -> 0 | E43: =IFERROR(C43-D43,0) -> 0
B44: Loisirs / Sorties | D44: =IFERROR(IF(B44="",0,SUMIFS(Transactions!$F:$F,Transactions!$G:$G,"Mai",Transactions!$D:$D,B44)),0) -> 0 | E44: =IFERROR(C44-D44,0) -> 0
B45: Restaurants / À emporter | D45: =IFERROR(IF(B45="",0,SUMIFS(Transactions!$F:$F,Transactions!$G:$G,"Mai",Transactions!$D:$D,B45)),0) -> 0 | E45: =IFERROR(C45-D45,0) -> 0
...

Sheet Juin
B2: Mon budget — Juin
B3: Le « Réel » se met à jour automatiquement depuis l'onglet Transactions.
B6: Catégorie | C6: Prévu | D6: Réel | E6: Écart
B7: Revenus
B8: Salaire parent 1 | D8: =IFERROR(IF(B8="",0,SUMIFS(Transactions!$F:$F,Transactions!$G:$G,"Juin",Transactions!$D:$D,B8)),0) -> 0 | E8: =IFERROR(C8-D8,0) -> 0
B9: Salaire parent 2 | D9: =IFERROR(IF(B9="",0,SUMIFS(Transactions!$F:$F,Transactions!$G:$G,"Juin",Transactions!$D:$D,B9)),0) -> 0 | E9: =IFERROR(C9-D9,0) -> 0
B10: Allocations familiales / CAF | D10: =IFERROR(IF(B10="",0,SUMIFS(Transactions!$F:$F,Transactions!$G:$G,"Juin",Transactions!$D:$D,B10)),0) -> 0 | E10: =IFERROR(C10-D10,0) -> 0
B11: Autres revenus | D11: =IFERROR(IF(B11="",0,SUMIFS(Transactions!$F:$F,Transactions!$G:$G,"Juin",Transactions!$D:$D,B11)),0) -> 0 | E11: =IFERROR(C11-D11,0) -> 0
D12: =IFERROR(IF(B12="",0,SUMIFS(Transactions!$F:$F,Transactions!$G:$G,"Juin",Transactions!$D:$D,B12)),0) -> 0 | E12: =IFERROR(C12-D12,0) -> 0
D13: =IFERROR(IF(B13="",0,SUMIFS(Transactions!$F:$F,Transactions!$G:$G,"Juin",Transactions!$D:$D,B13)),0) -> 0 | E13: =IFERROR(C13-D13,0) -> 0
D14: =IFERROR(IF(B14="",0,SUMIFS(Transactions!$F:$F,Transactions!$G:$G,"Juin",Transactions!$D:$D,B14)),0) -> 0 | E14: =IFERROR(C14-D14,0) -> 0
B15: Total revenus | C15: =SUM(C8:C14) -> 0 | D15: =SUM(D8:D14) -> 0 | E15: =SUM(E8:E14) -> 0
B17: Dépenses fixes
B18: Loyer / Crédit immobilier | D18: =IFERROR(IF(B18="",0,SUMIFS(Transactions!$F:$F,Transactions!$G:$G,"Juin",Transactions!$D:$D,B18)),0) -> 0 | E18: =IFERROR(C18-D18,0) -> 0
B19: Charges / Copropriété | D19: =IFERROR(IF(B19="",0,SUMIFS(Transactions!$F:$F,Transactions!$G:$G,"Juin",Transactions!$D:$D,B19)),0) -> 0 | E19: =IFERROR(C19-D19,0) -> 0
B20: Électricité / Gaz | D20: =IFERROR(IF(B20="",0,SUMIFS(Transactions!$F:$F,Transactions!$G:$G,"Juin",Transactions!$D:$D,B20)),0) -> 0 | E20: =IFERROR(C20-D20,0) -> 0
B21: Eau | D21: =IFERROR(IF(B21="",0,SUMIFS(Transactions!$F:$F,Transactions!$G:$G,"Juin",Transactions!$D:$D,B21)),0) -> 0 | E21: =IFERROR(C21-D21,0) -> 0
B22: Internet / Téléphone | D22: =IFERROR(IF(B22="",0,SUMIFS(Transactions!$F:$F,Transactions!$G:$G,"Juin",Transactions!$D:$D,B22)),0) -> 0 | E22: =IFERROR(C22-D22,0) -> 0
B23: Assurance habitation | D23: =IFERROR(IF(B23="",0,SUMIFS(Transactions!$F:$F,Transactions!$G:$G,"Juin",Transactions!$D:$D,B23)),0) -> 0 | E23: =IFERROR(C23-D23,0) -> 0
B24: Assurance voiture | D24: =IFERROR(IF(B24="",0,SUMIFS(Transactions!$F:$F,Transactions!$G:$G,"Juin",Transactions!$D:$D,B24)),0) -> 0 | E24: =IFERROR(C24-D24,0) -> 0
B25: Mutuelle santé | D25: =IFERROR(IF(B25="",0,SUMIFS(Transactions!$F:$F,Transactions!$G:$G,"Juin",Transactions!$D:$D,B25)),0) -> 0 | E25: =IFERROR(C25-D25,0) -> 0
B26: Impôts (prélèvement) | D26: =IFERROR(IF(B26="",0,SUMIFS(Transactions!$F:$F,Transactions!$G:$G,"Juin",Transactions!$D:$D,B26)),0) -> 0 | E26: =IFERROR(C26-D26,0) -> 0
B27: Crèche / Garde d'enfants | D27: =IFERROR(IF(B27="",0,SUMIFS(Transactions!$F:$F,Transactions!$G:$G,"Juin",Transactions!$D:$D,B27)),0) -> 0 | E27: =IFERROR(C27-D27,0) -> 0
B28: Cantine scolaire | D28: =IFERROR(IF(B28="",0,SUMIFS(Transactions!$F:$F,Transactions!$G:$G,"Juin",Transactions!$D:$D,B28)),0) -> 0 | E28: =IFERROR(C28-D28,0) -> 0
B29: Abonnements (streaming, salle…) | D29: =IFERROR(IF(B29="",0,SUMIFS(Transactions!$F:$F,Transactions!$G:$G,"Juin",Transactions!$D:$D,B29)),0) -> 0 | E29: =IFERROR(C29-D29,0) -> 0
D30: =IFERROR(IF(B30="",0,SUMIFS(Transactions!$F:$F,Transactions!$G:$G,"Juin",Transactions!$D:$D,B30)),0) -> 0 | E30: =IFERROR(C30-D30,0) -> 0
D31: =IFERROR(IF(B31="",0,SUMIFS(Transactions!$F:$F,Transactions!$G:$G,"Juin",Transactions!$D:$D,B31)),0) -> 0 | E31: =IFERROR(C31-D31,0) -> 0
D32: =IFERROR(IF(B32="",0,SUMIFS(Transactions!$F:$F,Transactions!$G:$G,"Juin",Transactions!$D:$D,B32)),0) -> 0 | E32: =IFERROR(C32-D32,0) -> 0
D33: =IFERROR(IF(B33="",0,SUMIFS(Transactions!$F:$F,Transactions!$G:$G,"Juin",Transactions!$D:$D,B33)),0) -> 0 | E33: =IFERROR(C33-D33,0) -> 0
D34: =IFERROR(IF(B34="",0,SUMIFS(Transactions!$F:$F,Transactions!$G:$G,"Juin",Transactions!$D:$D,B34)),0) -> 0 | E34: =IFERROR(C34-D34,0) -> 0
D35: =IFERROR(IF(B35="",0,SUMIFS(Transactions!$F:$F,Transactions!$G:$G,"Juin",Transactions!$D:$D,B35)),0) -> 0 | E35: =IFERROR(C35-D35,0) -> 0
B36: Total dépenses fixes | C36: =SUM(C18:C35) -> 0 | D36: =SUM(D18:D35) -> 0 | E36: =SUM(E18:E35) -> 0
B38: Dépenses courantes
B39: Courses alimentaires | D39: =IFERROR(IF(B39="",0,SUMIFS(Transactions!$F:$F,Transactions!$G:$G,"Juin",Transactions!$D:$D,B39)),0) -> 0 | E39: =IFERROR(C39-D39,0) -> 0
B40: Transport / Carburant | D40: =IFERROR(IF(B40="",0,SUMIFS(Transactions!$F:$F,Transactions!$G:$G,"Juin",Transactions!$D:$D,B40)),0) -> 0 | E40: =IFERROR(C40-D40,0) -> 0
B41: Vêtements famille | D41: =IFERROR(IF(B41="",0,SUMIFS(Transactions!$F:$F,Transactions!$G:$G,"Juin",Transactions!$D:$D,B41)),0) -> 0 | E41: =IFERROR(C41-D41,0) -> 0
B42: Enfants (fournitures, activités) | D42: =IFERROR(IF(B42="",0,SUMIFS(Transactions!$F:$F,Transactions!$G:$G,"Juin",Transactions!$D:$D,B42)),0) -> 0 | E42: =IFERROR(C42-D42,0) -> 0
B43: Santé (pharmacie, médecin) | D43: =IFERROR(IF(B43="",0,SUMIFS(Transactions!$F:$F,Transactions!$G:$G,"Juin",Transactions!$D:$D,B43)),0) -> 0 | E43: =IFERROR(C43-D43,0) -> 0
B44: Loisirs / Sorties | D44: =IFERROR(IF(B44="",0,SUMIFS(Transactions!$F:$F,Transactions!$G:$G,"Juin",Transactions!$D:$D,B44)),0) -> 0 | E44: =IFERROR(C44-D44,0) -> 0
B45: Restaurants / À emporter | D45: =IFERROR(IF(B45="",0,SUMIFS(Transactions!$F:$F,Transactions!$G:$G,"Juin",Transactions!$D:$D,B45)),0) -> 0 | E45: =IFERROR(C45-D45,0) -> 0
...

Sheet Juillet
B2: Mon budget — Juillet
B3: Le « Réel » se met à jour automatiquement depuis l'onglet Transactions.
B6: Catégorie | C6: Prévu | D6: Réel | E6: Écart
B7: Revenus
B8: Salaire parent 1 | D8: =IFERROR(IF(B8="",0,SUMIFS(Transactions!$F:$F,Transactions!$G:$G,"Juillet",Transactions!$D:$D,B8)),0) -> 0 | E8: =IFERROR(C8-D8,0) -> 0
B9: Salaire parent 2 | D9: =IFERROR(IF(B9="",0,SUMIFS(Transactions!$F:$F,Transactions!$G:$G,"Juillet",Transactions!$D:$D,B9)),0) -> 0 | E9: =IFERROR(C9-D9,0) -> 0
B10: Allocations familiales / CAF | D10: =IFERROR(IF(B10="",0,SUMIFS(Transactions!$F:$F,Transactions!$G:$G,"Juillet",Transactions!$D:$D,B10)),0) -> 0 | E10: =IFERROR(C10-D10,0) -> 0
B11: Autres revenus | D11: =IFERROR(IF(B11="",0,SUMIFS(Transactions!$F:$F,Transactions!$G:$G,"Juillet",Transactions!$D:$D,B11)),0) -> 0 | E11: =IFERROR(C11-D11,0) -> 0
D12: =IFERROR(IF(B12="",0,SUMIFS(Transactions!$F:$F,Transactions!$G:$G,"Juillet",Transactions!$D:$D,B12)),0) -> 0 | E12: =IFERROR(C12-D12,0) -> 0
D13: =IFERROR(IF(B13="",0,SUMIFS(Transactions!$F:$F,Transactions!$G:$G,"Juillet",Transactions!$D:$D,B13)),0) -> 0 | E13: =IFERROR(C13-D13,0) -> 0
D14: =IFERROR(IF(B14="",0,SUMIFS(Transactions!$F:$F,Transactions!$G:$G,"Juillet",Transactions!$D:$D,B14)),0) -> 0 | E14: =IFERROR(C14-D14,0) -> 0
B15: Total revenus | C15: =SUM(C8:C14) -> 0 | D15: =SUM(D8:D14) -> 0 | E15: =SUM(E8:E14) -> 0
B17: Dépenses fixes
B18: Loyer / Crédit immobilier | D18: =IFERROR(IF(B18="",0,SUMIFS(Transactions!$F:$F,Transactions!$G:$G,"Juillet",Transactions!$D:$D,B18)),0) -> 0 | E18: =IFERROR(C18-D18,0) -> 0
B19: Charges / Copropriété | D19: =IFERROR(IF(B19="",0,SUMIFS(Transactions!$F:$F,Transactions!$G:$G,"Juillet",Transactions!$D:$D,B19)),0) -> 0 | E19: =IFERROR(C19-D19,0) -> 0
B20: Électricité / Gaz | D20: =IFERROR(IF(B20="",0,SUMIFS(Transactions!$F:$F,Transactions!$G:$G,"Juillet",Transactions!$D:$D,B20)),0) -> 0 | E20: =IFERROR(C20-D20,0) -> 0
B21: Eau | D21: =IFERROR(IF(B21="",0,SUMIFS(Transactions!$F:$F,Transactions!$G:$G,"Juillet",Transactions!$D:$D,B21)),0) -> 0 | E21: =IFERROR(C21-D21,0) -> 0
B22: Internet / Téléphone | D22: =IFERROR(IF(B22="",0,SUMIFS(Transactions!$F:$F,Transactions!$G:$G,"Juillet",Transactions!$D:$D,B22)),0) -> 0 | E22: =IFERROR(C22-D22,0) -> 0
B23: Assurance habitation | D23: =IFERROR(IF(B23="",0,SUMIFS(Transactions!$F:$F,Transactions!$G:$G,"Juillet",Transactions!$D:$D,B23)),0) -> 0 | E23: =IFERROR(C23-D23,0) -> 0
B24: Assurance voiture | D24: =IFERROR(IF(B24="",0,SUMIFS(Transactions!$F:$F,Transactions!$G:$G,"Juillet",Transactions!$D:$D,B24)),0) -> 0 | E24: =IFERROR(C24-D24,0) -> 0
B25: Mutuelle santé | D25: =IFERROR(IF(B25="",0,SUMIFS(Transactions!$F:$F,Transactions!$G:$G,"Juillet",Transactions!$D:$D,B25)),0) -> 0 | E25: =IFERROR(C25-D25,0) -> 0
B26: Impôts (prélèvement) | D26: =IFERROR(IF(B26="",0,SUMIFS(Transactions!$F:$F,Transactions!$G:$G,"Juillet",Transactions!$D:$D,B26)),0) -> 0 | E26: =IFERROR(C26-D26,0) -> 0
B27: Crèche / Garde d'enfants | D27: =IFERROR(IF(B27="",0,SUMIFS(Transactions!$F:$F,Transactions!$G:$G,"Juillet",Transactions!$D:$D,B27)),0) -> 0 | E27: =IFERROR(C27-D27,0) -> 0
B28: Cantine scolaire | D28: =IFERROR(IF(B28="",0,SUMIFS(Transactions!$F:$F,Transactions!$G:$G,"Juillet",Transactions!$D:$D,B28)),0) -> 0 | E28: =IFERROR(C28-D28,0) -> 0
B29: Abonnements (streaming, salle…) | D29: =IFERROR(IF(B29="",0,SUMIFS(Transactions!$F:$F,Transactions!$G:$G,"Juillet",Transactions!$D:$D,B29)),0) -> 0 | E29: =IFERROR(C29-D29,0) -> 0
D30: =IFERROR(IF(B30="",0,SUMIFS(Transactions!$F:$F,Transactions!$G:$G,"Juillet",Transactions!$D:$D,B30)),0) -> 0 | E30: =IFERROR(C30-D30,0) -> 0
D31: =IFERROR(IF(B31="",0,SUMIFS(Transactions!$F:$F,Transactions!$G:$G,"Juillet",Transactions!$D:$D,B31)),0) -> 0 | E31: =IFERROR(C31-D31,0) -> 0
D32: =IFERROR(IF(B32="",0,SUMIFS(Transactions!$F:$F,Transactions!$G:$G,"Juillet",Transactions!$D:$D,B32)),0) -> 0 | E32: =IFERROR(C32-D32,0) -> 0
D33: =IFERROR(IF(B33="",0,SUMIFS(Transactions!$F:$F,Transactions!$G:$G,"Juillet",Transactions!$D:$D,B33)),0) -> 0 | E33: =IFERROR(C33-D33,0) -> 0
D34: =IFERROR(IF(B34="",0,SUMIFS(Transactions!$F:$F,Transactions!$G:$G,"Juillet",Transactions!$D:$D,B34)),0) -> 0 | E34: =IFERROR(C34-D34,0) -> 0
D35: =IFERROR(IF(B35="",0,SUMIFS(Transactions!$F:$F,Transactions!$G:$G,"Juillet",Transactions!$D:$D,B35)),0) -> 0 | E35: =IFERROR(C35-D35,0) -> 0
B36: Total dépenses fixes | C36: =SUM(C18:C35) -> 0 | D36: =SUM(D18:D35) -> 0 | E36: =SUM(E18:E35) -> 0
B38: Dépenses courantes
B39: Courses alimentaires | D39: =IFERROR(IF(B39="",0,SUMIFS(Transactions!$F:$F,Transactions!$G:$G,"Juillet",Transactions!$D:$D,B39)),0) -> 0 | E39: =IFERROR(C39-D39,0) -> 0
B40: Transport / Carburant | D40: =IFERROR(IF(B40="",0,SUMIFS(Transactions!$F:$F,Transactions!$G:$G,"Juillet",Transactions!$D:$D,B40)),0) -> 0 | E40: =IFERROR(C40-D40,0) -> 0
B41: Vêtements famille | D41: =IFERROR(IF(B41="",0,SUMIFS(Transactions!$F:$F,Transactions!$G:$G,"Juillet",Transactions!$D:$D,B41)),0) -> 0 | E41: =IFERROR(C41-D41,0) -> 0
B42: Enfants (fournitures, activités) | D42: =IFERROR(IF(B42="",0,SUMIFS(Transactions!$F:$F,Transactions!$G:$G,"Juillet",Transactions!$D:$D,B42)),0) -> 0 | E42: =IFERROR(C42-D42,0) -> 0
B43: Santé (pharmacie, médecin) | D43: =IFERROR(IF(B43="",0,SUMIFS(Transactions!$F:$F,Transactions!$G:$G,"Juillet",Transactions!$D:$D,B43)),0) -> 0 | E43: =IFERROR(C43-D43,0) -> 0
B44: Loisirs / Sorties | D44: =IFERROR(IF(B44="",0,SUMIFS(Transactions!$F:$F,Transactions!$G:$G,"Juillet",Transactions!$D:$D,B44)),0) -> 0 | E44: =IFERROR(C44-D44,0) -> 0
B45: Restaurants / À emporter | D45: =IFERROR(IF(B45="",0,SUMIFS(Transactions!$F:$F,Transactions!$G:$G,"Juillet",Transactions!$D:$D,B45)),0) -> 0 | E45: =IFERROR(C45-D45,0) -> 0
...

Sheet Août
B2: Mon budget — Août
B3: Le « Réel » se met à jour automatiquement depuis l'onglet Transactions.
B6: Catégorie | C6: Prévu | D6: Réel | E6: Écart
B7: Revenus
B8: Salaire parent 1 | D8: =IFERROR(IF(B8="",0,SUMIFS(Transactions!$F:$F,Transactions!$G:$G,"Août",Transactions!$D:$D,B8)),0) -> 0 | E8: =IFERROR(C8-D8,0) -> 0
B9: Salaire parent 2 | D9: =IFERROR(IF(B9="",0,SUMIFS(Transactions!$F:$F,Transactions!$G:$G,"Août",Transactions!$D:$D,B9)),0) -> 0 | E9: =IFERROR(C9-D9,0) -> 0
B10: Allocations familiales / CAF | D10: =IFERROR(IF(B10="",0,SUMIFS(Transactions!$F:$F,Transactions!$G:$G,"Août",Transactions!$D:$D,B10)),0) -> 0 | E10: =IFERROR(C10-D10,0) -> 0
B11: Autres revenus | D11: =IFERROR(IF(B11="",0,SUMIFS(Transactions!$F:$F,Transactions!$G:$G,"Août",Transactions!$D:$D,B11)),0) -> 0 | E11: =IFERROR(C11-D11,0) -> 0
D12: =IFERROR(IF(B12="",0,SUMIFS(Transactions!$F:$F,Transactions!$G:$G,"Août",Transactions!$D:$D,B12)),0) -> 0 | E12: =IFERROR(C12-D12,0) -> 0
D13: =IFERROR(IF(B13="",0,SUMIFS(Transactions!$F:$F,Transactions!$G:$G,"Août",Transactions!$D:$D,B13)),0) -> 0 | E13: =IFERROR(C13-D13,0) -> 0
D14: =IFERROR(IF(B14="",0,SUMIFS(Transactions!$F:$F,Transactions!$G:$G,"Août",Transactions!$D:$D,B14)),0) -> 0 | E14: =IFERROR(C14-D14,0) -> 0
B15: Total revenus | C15: =SUM(C8:C14) -> 0 | D15: =SUM(D8:D14) -> 0 | E15: =SUM(E8:E14) -> 0
B17: Dépenses fixes
B18: Loyer / Crédit immobilier | D18: =IFERROR(IF(B18="",0,SUMIFS(Transactions!$F:$F,Transactions!$G:$G,"Août",Transactions!$D:$D,B18)),0) -> 0 | E18: =IFERROR(C18-D18,0) -> 0
B19: Charges / Copropriété | D19: =IFERROR(IF(B19="",0,SUMIFS(Transactions!$F:$F,Transactions!$G:$G,"Août",Transactions!$D:$D,B19)),0) -> 0 | E19: =IFERROR(C19-D19,0) -> 0
B20: Électricité / Gaz | D20: =IFERROR(IF(B20="",0,SUMIFS(Transactions!$F:$F,Transactions!$G:$G,"Août",Transactions!$D:$D,B20)),0) -> 0 | E20: =IFERROR(C20-D20,0) -> 0
B21: Eau | D21: =IFERROR(IF(B21="",0,SUMIFS(Transactions!$F:$F,Transactions!$G:$G,"Août",Transactions!$D:$D,B21)),0) -> 0 | E21: =IFERROR(C21-D21,0) -> 0
B22: Internet / Téléphone | D22: =IFERROR(IF(B22="",0,SUMIFS(Transactions!$F:$F,Transactions!$G:$G,"Août",Transactions!$D:$D,B22)),0) -> 0 | E22: =IFERROR(C22-D22,0) -> 0
B23: Assurance habitation | D23: =IFERROR(IF(B23="",0,SUMIFS(Transactions!$F:$F,Transactions!$G:$G,"Août",Transactions!$D:$D,B23)),0) -> 0 | E23: =IFERROR(C23-D23,0) -> 0
B24: Assurance voiture | D24: =IFERROR(IF(B24="",0,SUMIFS(Transactions!$F:$F,Transactions!$G:$G,"Août",Transactions!$D:$D,B24)),0) -> 0 | E24: =IFERROR(C24-D24,0) -> 0
B25: Mutuelle santé | D25: =IFERROR(IF(B25="",0,SUMIFS(Transactions!$F:$F,Transactions!$G:$G,"Août",Transactions!$D:$D,B25)),0) -> 0 | E25: =IFERROR(C25-D25,0) -> 0
B26: Impôts (prélèvement) | D26: =IFERROR(IF(B26="",0,SUMIFS(Transactions!$F:$F,Transactions!$G:$G,"Août",Transactions!$D:$D,B26)),0) -> 0 | E26: =IFERROR(C26-D26,0) -> 0
B27: Crèche / Garde d'enfants | D27: =IFERROR(IF(B27="",0,SUMIFS(Transactions!$F:$F,Transactions!$G:$G,"Août",Transactions!$D:$D,B27)),0) -> 0 | E27: =IFERROR(C27-D27,0) -> 0
B28: Cantine scolaire | D28: =IFERROR(IF(B28="",0,SUMIFS(Transactions!$F:$F,Transactions!$G:$G,"Août",Transactions!$D:$D,B28)),0) -> 0 | E28: =IFERROR(C28-D28,0) -> 0
B29: Abonnements (streaming, salle…) | D29: =IFERROR(IF(B29="",0,SUMIFS(Transactions!$F:$F,Transactions!$G:$G,"Août",Transactions!$D:$D,B29)),0) -> 0 | E29: =IFERROR(C29-D29,0) -> 0
D30: =IFERROR(IF(B30="",0,SUMIFS(Transactions!$F:$F,Transactions!$G:$G,"Août",Transactions!$D:$D,B30)),0) -> 0 | E30: =IFERROR(C30-D30,0) -> 0
D31: =IFERROR(IF(B31="",0,SUMIFS(Transactions!$F:$F,Transactions!$G:$G,"Août",Transactions!$D:$D,B31)),0) -> 0 | E31: =IFERROR(C31-D31,0) -> 0
D32: =IFERROR(IF(B32="",0,SUMIFS(Transactions!$F:$F,Transactions!$G:$G,"Août",Transactions!$D:$D,B32)),0) -> 0 | E32: =IFERROR(C32-D32,0) -> 0
D33: =IFERROR(IF(B33="",0,SUMIFS(Transactions!$F:$F,Transactions!$G:$G,"Août",Transactions!$D:$D,B33)),0) -> 0 | E33: =IFERROR(C33-D33,0) -> 0
D34: =IFERROR(IF(B34="",0,SUMIFS(Transactions!$F:$F,Transactions!$G:$G,"Août",Transactions!$D:$D,B34)),0) -> 0 | E34: =IFERROR(C34-D34,0) -> 0
D35: =IFERROR(IF(B35="",0,SUMIFS(Transactions!$F:$F,Transactions!$G:$G,"Août",Transactions!$D:$D,B35)),0) -> 0 | E35: =IFERROR(C35-D35,0) -> 0
B36: Total dépenses fixes | C36: =SUM(C18:C35) -> 0 | D36: =SUM(D18:D35) -> 0 | E36: =SUM(E18:E35) -> 0
B38: Dépenses courantes
B39: Courses alimentaires | D39: =IFERROR(IF(B39="",0,SUMIFS(Transactions!$F:$F,Transactions!$G:$G,"Août",Transactions!$D:$D,B39)),0) -> 0 | E39: =IFERROR(C39-D39,0) -> 0
B40: Transport / Carburant | D40: =IFERROR(IF(B40="",0,SUMIFS(Transactions!$F:$F,Transactions!$G:$G,"Août",Transactions!$D:$D,B40)),0) -> 0 | E40: =IFERROR(C40-D40,0) -> 0
B41: Vêtements famille | D41: =IFERROR(IF(B41="",0,SUMIFS(Transactions!$F:$F,Transactions!$G:$G,"Août",Transactions!$D:$D,B41)),0) -> 0 | E41: =IFERROR(C41-D41,0) -> 0
B42: Enfants (fournitures, activités) | D42: =IFERROR(IF(B42="",0,SUMIFS(Transactions!$F:$F,Transactions!$G:$G,"Août",Transactions!$D:$D,B42)),0) -> 0 | E42: =IFERROR(C42-D42,0) -> 0
B43: Santé (pharmacie, médecin) | D43: =IFERROR(IF(B43="",0,SUMIFS(Transactions!$F:$F,Transactions!$G:$G,"Août",Transactions!$D:$D,B43)),0) -> 0 | E43: =IFERROR(C43-D43,0) -> 0
B44: Loisirs / Sorties | D44: =IFERROR(IF(B44="",0,SUMIFS(Transactions!$F:$F,Transactions!$G:$G,"Août",Transactions!$D:$D,B44)),0) -> 0 | E44: =IFERROR(C44-D44,0) -> 0
B45: Restaurants / À emporter | D45: =IFERROR(IF(B45="",0,SUMIFS(Transactions!$F:$F,Transactions!$G:$G,"Août",Transactions!$D:$D,B45)),0) -> 0 | E45: =IFERROR(C45-D45,0) -> 0
...

Sheet Septembre
B2: Mon budget — Septembre
B3: Le « Réel » se met à jour automatiquement depuis l'onglet Transactions.
B6: Catégorie | C6: Prévu | D6: Réel | E6: Écart
B7: Revenus
B8: Salaire parent 1 | D8: =IFERROR(IF(B8="",0,SUMIFS(Transactions!$F:$F,Transactions!$G:$G,"Septembre",Transactions!$D:$D,B8)),0) -> 0 | E8: =IFERROR(C8-D8,0) -> 0
B9: Salaire parent 2 | D9: =IFERROR(IF(B9="",0,SUMIFS(Transactions!$F:$F,Transactions!$G:$G,"Septembre",Transactions!$D:$D,B9)),0) -> 0 | E9: =IFERROR(C9-D9,0) -> 0
B10: Allocations familiales / CAF | D10: =IFERROR(IF(B10="",0,SUMIFS(Transactions!$F:$F,Transactions!$G:$G,"Septembre",Transactions!$D:$D,B10)),0) -> 0 | E10: =IFERROR(C10-D10,0) -> 0
B11: Autres revenus | D11: =IFERROR(IF(B11="",0,SUMIFS(Transactions!$F:$F,Transactions!$G:$G,"Septembre",Transactions!$D:$D,B11)),0) -> 0 | E11: =IFERROR(C11-D11,0) -> 0
D12: =IFERROR(IF(B12="",0,SUMIFS(Transactions!$F:$F,Transactions!$G:$G,"Septembre",Transactions!$D:$D,B12)),0) -> 0 | E12: =IFERROR(C12-D12,0) -> 0
D13: =IFERROR(IF(B13="",0,SUMIFS(Transactions!$F:$F,Transactions!$G:$G,"Septembre",Transactions!$D:$D,B13)),0) -> 0 | E13: =IFERROR(C13-D13,0) -> 0
D14: =IFERROR(IF(B14="",0,SUMIFS(Transactions!$F:$F,Transactions!$G:$G,"Septembre",Transactions!$D:$D,B14)),0) -> 0 | E14: =IFERROR(C14-D14,0) -> 0
B15: Total revenus | C15: =SUM(C8:C14) -> 0 | D15: =SUM(D8:D14) -> 0 | E15: =SUM(E8:E14) -> 0
B17: Dépenses fixes
B18: Loyer / Crédit immobilier | D18: =IFERROR(IF(B18="",0,SUMIFS(Transactions!$F:$F,Transactions!$G:$G,"Septembre",Transactions!$D:$D,B18)),0) -> 0 | E18: =IFERROR(C18-D18,0) -> 0
B19: Charges / Copropriété | D19: =IFERROR(IF(B19="",0,SUMIFS(Transactions!$F:$F,Transactions!$G:$G,"Septembre",Transactions!$D:$D,B19)),0) -> 0 | E19: =IFERROR(C19-D19,0) -> 0
B20: Électricité / Gaz | D20: =IFERROR(IF(B20="",0,SUMIFS(Transactions!$F:$F,Transactions!$G:$G,"Septembre",Transactions!$D:$D,B20)),0) -> 0 | E20: =IFERROR(C20-D20,0) -> 0
B21: Eau | D21: =IFERROR(IF(B21="",0,SUMIFS(Transactions!$F:$F,Transactions!$G:$G,"Septembre",Transactions!$D:$D,B21)),0) -> 0 | E21: =IFERROR(C21-D21,0) -> 0
B22: Internet / Téléphone | D22: =IFERROR(IF(B22="",0,SUMIFS(Transactions!$F:$F,Transactions!$G:$G,"Septembre",Transactions!$D:$D,B22)),0) -> 0 | E22: =IFERROR(C22-D22,0) -> 0
B23: Assurance habitation | D23: =IFERROR(IF(B23="",0,SUMIFS(Transactions!$F:$F,Transactions!$G:$G,"Septembre",Transactions!$D:$D,B23)),0) -> 0 | E23: =IFERROR(C23-D23,0) -> 0
B24: Assurance voiture | D24: =IFERROR(IF(B24="",0,SUMIFS(Transactions!$F:$F,Transactions!$G:$G,"Septembre",Transactions!$D:$D,B24)),0) -> 0 | E24: =IFERROR(C24-D24,0) -> 0
B25: Mutuelle santé | D25: =IFERROR(IF(B25="",0,SUMIFS(Transactions!$F:$F,Transactions!$G:$G,"Septembre",Transactions!$D:$D,B25)),0) -> 0 | E25: =IFERROR(C25-D25,0) -> 0
B26: Impôts (prélèvement) | D26: =IFERROR(IF(B26="",0,SUMIFS(Transactions!$F:$F,Transactions!$G:$G,"Septembre",Transactions!$D:$D,B26)),0) -> 0 | E26: =IFERROR(C26-D26,0) -> 0
B27: Crèche / Garde d'enfants | D27: =IFERROR(IF(B27="",0,SUMIFS(Transactions!$F:$F,Transactions!$G:$G,"Septembre",Transactions!$D:$D,B27)),0) -> 0 | E27: =IFERROR(C27-D27,0) -> 0
B28: Cantine scolaire | D28: =IFERROR(IF(B28="",0,SUMIFS(Transactions!$F:$F,Transactions!$G:$G,"Septembre",Transactions!$D:$D,B28)),0) -> 0 | E28: =IFERROR(C28-D28,0) -> 0
B29: Abonnements (streaming, salle…) | D29: =IFERROR(IF(B29="",0,SUMIFS(Transactions!$F:$F,Transactions!$G:$G,"Septembre",Transactions!$D:$D,B29)),0) -> 0 | E29: =IFERROR(C29-D29,0) -> 0
D30: =IFERROR(IF(B30="",0,SUMIFS(Transactions!$F:$F,Transactions!$G:$G,"Septembre",Transactions!$D:$D,B30)),0) -> 0 | E30: =IFERROR(C30-D30,0) -> 0
D31: =IFERROR(IF(B31="",0,SUMIFS(Transactions!$F:$F,Transactions!$G:$G,"Septembre",Transactions!$D:$D,B31)),0) -> 0 | E31: =IFERROR(C31-D31,0) -> 0
D32: =IFERROR(IF(B32="",0,SUMIFS(Transactions!$F:$F,Transactions!$G:$G,"Septembre",Transactions!$D:$D,B32)),0) -> 0 | E32: =IFERROR(C32-D32,0) -> 0
D33: =IFERROR(IF(B33="",0,SUMIFS(Transactions!$F:$F,Transactions!$G:$G,"Septembre",Transactions!$D:$D,B33)),0) -> 0 | E33: =IFERROR(C33-D33,0) -> 0
D34: =IFERROR(IF(B34="",0,SUMIFS(Transactions!$F:$F,Transactions!$G:$G,"Septembre",Transactions!$D:$D,B34)),0) -> 0 | E34: =IFERROR(C34-D34,0) -> 0
D35: =IFERROR(IF(B35="",0,SUMIFS(Transactions!$F:$F,Transactions!$G:$G,"Septembre",Transactions!$D:$D,B35)),0) -> 0 | E35: =IFERROR(C35-D35,0) -> 0
B36: Total dépenses fixes | C36: =SUM(C18:C35) -> 0 | D36: =SUM(D18:D35) -> 0 | E36: =SUM(E18:E35) -> 0
B38: Dépenses courantes
B39: Courses alimentaires | D39: =IFERROR(IF(B39="",0,SUMIFS(Transactions!$F:$F,Transactions!$G:$G,"Septembre",Transactions!$D:$D,B39)),0) -> 0 | E39: =IFERROR(C39-D39,0) -> 0
B40: Transport / Carburant | D40: =IFERROR(IF(B40="",0,SUMIFS(Transactions!$F:$F,Transactions!$G:$G,"Septembre",Transactions!$D:$D,B40)),0) -> 0 | E40: =IFERROR(C40-D40,0) -> 0
B41: Vêtements famille | D41: =IFERROR(IF(B41="",0,SUMIFS(Transactions!$F:$F,Transactions!$G:$G,"Septembre",Transactions!$D:$D,B41)),0) -> 0 | E41: =IFERROR(C41-D41,0) -> 0
B42: Enfants (fournitures, activités) | D42: =IFERROR(IF(B42="",0,SUMIFS(Transactions!$F:$F,Transactions!$G:$G,"Septembre",Transactions!$D:$D,B42)),0) -> 0 | E42: =IFERROR(C42-D42,0) -> 0
B43: Santé (pharmacie, médecin) | D43: =IFERROR(IF(B43="",0,SUMIFS(Transactions!$F:$F,Transactions!$G:$G,"Septembre",Transactions!$D:$D,B43)),0) -> 0 | E43: =IFERROR(C43-D43,0) -> 0
B44: Loisirs / Sorties | D44: =IFERROR(IF(B44="",0,SUMIFS(Transactions!$F:$F,Transactions!$G:$G,"Septembre",Transactions!$D:$D,B44)),0) -> 0 | E44: =IFERROR(C44-D44,0) -> 0
B45: Restaurants / À emporter | D45: =IFERROR(IF(B45="",0,SUMIFS(Transactions!$F:$F,Transactions!$G:$G,"Septembre",Transactions!$D:$D,B45)),0) -> 0 | E45: =IFERROR(C45-D45,0) -> 0
...

Sheet Octobre
B2: Mon budget — Octobre
B3: Le « Réel » se met à jour automatiquement depuis l'onglet Transactions.
B6: Catégorie | C6: Prévu | D6: Réel | E6: Écart
B7: Revenus
B8: Salaire parent 1 | D8: =IFERROR(IF(B8="",0,SUMIFS(Transactions!$F:$F,Transactions!$G:$G,"Octobre",Transactions!$D:$D,B8)),0) -> 0 | E8: =IFERROR(C8-D8,0) -> 0
B9: Salaire parent 2 | D9: =IFERROR(IF(B9="",0,SUMIFS(Transactions!$F:$F,Transactions!$G:$G,"Octobre",Transactions!$D:$D,B9)),0) -> 0 | E9: =IFERROR(C9-D9,0) -> 0
B10: Allocations familiales / CAF | D10: =IFERROR(IF(B10="",0,SUMIFS(Transactions!$F:$F,Transactions!$G:$G,"Octobre",Transactions!$D:$D,B10)),0) -> 0 | E10: =IFERROR(C10-D10,0) -> 0
B11: Autres revenus | D11: =IFERROR(IF(B11="",0,SUMIFS(Transactions!$F:$F,Transactions!$G:$G,"Octobre",Transactions!$D:$D,B11)),0) -> 0 | E11: =IFERROR(C11-D11,0) -> 0
D12: =IFERROR(IF(B12="",0,SUMIFS(Transactions!$F:$F,Transactions!$G:$G,"Octobre",Transactions!$D:$D,B12)),0) -> 0 | E12: =IFERROR(C12-D12,0) -> 0
D13: =IFERROR(IF(B13="",0,SUMIFS(Transactions!$F:$F,Transactions!$G:$G,"Octobre",Transactions!$D:$D,B13)),0) -> 0 | E13: =IFERROR(C13-D13,0) -> 0
D14: =IFERROR(IF(B14="",0,SUMIFS(Transactions!$F:$F,Transactions!$G:$G,"Octobre",Transactions!$D:$D,B14)),0) -> 0 | E14: =IFERROR(C14-D14,0) -> 0
B15: Total revenus | C15: =SUM(C8:C14) -> 0 | D15: =SUM(D8:D14) -> 0 | E15: =SUM(E8:E14) -> 0
B17: Dépenses fixes
B18: Loyer / Crédit immobilier | D18: =IFERROR(IF(B18="",0,SUMIFS(Transactions!$F:$F,Transactions!$G:$G,"Octobre",Transactions!$D:$D,B18)),0) -> 0 | E18: =IFERROR(C18-D18,0) -> 0
B19: Charges / Copropriété | D19: =IFERROR(IF(B19="",0,SUMIFS(Transactions!$F:$F,Transactions!$G:$G,"Octobre",Transactions!$D:$D,B19)),0) -> 0 | E19: =IFERROR(C19-D19,0) -> 0
B20: Électricité / Gaz | D20: =IFERROR(IF(B20="",0,SUMIFS(Transactions!$F:$F,Transactions!$G:$G,"Octobre",Transactions!$D:$D,B20)),0) -> 0 | E20: =IFERROR(C20-D20,0) -> 0
B21: Eau | D21: =IFERROR(IF(B21="",0,SUMIFS(Transactions!$F:$F,Transactions!$G:$G,"Octobre",Transactions!$D:$D,B21)),0) -> 0 | E21: =IFERROR(C21-D21,0) -> 0
B22: Internet / Téléphone | D22: =IFERROR(IF(B22="",0,SUMIFS(Transactions!$F:$F,Transactions!$G:$G,"Octobre",Transactions!$D:$D,B22)),0) -> 0 | E22: =IFERROR(C22-D22,0) -> 0
B23: Assurance habitation | D23: =IFERROR(IF(B23="",0,SUMIFS(Transactions!$F:$F,Transactions!$G:$G,"Octobre",Transactions!$D:$D,B23)),0) -> 0 | E23: =IFERROR(C23-D23,0) -> 0
B24: Assurance voiture | D24: =IFERROR(IF(B24="",0,SUMIFS(Transactions!$F:$F,Transactions!$G:$G,"Octobre",Transactions!$D:$D,B24)),0) -> 0 | E24: =IFERROR(C24-D24,0) -> 0
B25: Mutuelle santé | D25: =IFERROR(IF(B25="",0,SUMIFS(Transactions!$F:$F,Transactions!$G:$G,"Octobre",Transactions!$D:$D,B25)),0) -> 0 | E25: =IFERROR(C25-D25,0) -> 0
B26: Impôts (prélèvement) | D26: =IFERROR(IF(B26="",0,SUMIFS(Transactions!$F:$F,Transactions!$G:$G,"Octobre",Transactions!$D:$D,B26)),0) -> 0 | E26: =IFERROR(C26-D26,0) -> 0
